Workbook

Sheet Revision History
A1: Revision History
A3: Version No. | B3: Description of Change | C3: Prepared by | D3: Revised Date
A4: 0.1 | B4: Initial version | C4: อนุชา พิมสร้อย | D4: 46199
A5: 1 | B5: Baseline version
A7: Signature
A9: Application | B9: Project Role | C9: Name | D9: Division | E9: Signature | F9: Sign Date
A10: Enterprise Data Warehouse | B10: PM | C10: วโรตม์ สุนทรารัตน์พงษ์ | D10: ฝ่ายวิจัยและพัฒนาเทคโนโลยีสารสนเทศ | E10: วโรตม์ สุนทรารัตน์พงษ์ | F10: 46199
A11: Enterprise Data Warehouse | B11: Lead SA | C11: ณภัค พิชิตกุศลาชัย | D11: ฝ่ายวิจัยและพัฒนาเทคโนโลยีสารสนเทศ | E11: ณภัค พิชิตกุศลาชัย | F11: 46199
A12: Enterprise Data Warehouse | B12: SA | D12: ฝ่ายวิจัยและพัฒนาเทคโนโลยีสารสนเทศ | F12: 46199
A13: Enterprise Data Warehouse | B13: Lead Developer | C13: อภิมุข ดำอ่อน | D13: ฝ่ายวิจัยและพัฒนาเทคโนโลยีสารสนเทศ | E13: อภิมุข ดำอ่อน | F13: 46199
A14: Enterprise Data Warehouse | B14: Developer | C14: อภิมุข ดำอ่อน | D14: ฝ่ายวิจัยและพัฒนาเทคโนโลยีสารสนเทศ | E14: อภิมุข ดำอ่อน | F14: 46199
A15: Enterprise Data Warehouse | B15: Lead Test | C15: อนุชา พิมสร้อย | D15: ฝ่ายวิจัยและพัฒนาเทคโนโลยีสารสนเทศ | E15: อนุชา พิมสร้อย | F15: 46199
A16: Enterprise Data Warehouse | B16: Tester | C16: ชุติมา สมพันธ์แพ | D16: ฝ่ายวิจัยและพัฒนาเทคโนโลยีสารสนเทศ | E16: ชุติมา สมพันธ์แพ | F16: 46199

Sheet Test Summary
A1: Test Summary Report
A3: Project Code | B3: 20260040
A4: Project Name | B4: Improvement for OIC timeline (ปรับปรุง R- Report)
A5: Project Manager | B5: วโรตม์ สุนทรารัตน์พงษ์
A6: Test Phase | B6: SIT
A7: Report Date | B7: =today() -> 46205
A8: Plan Timeline | B8: 46199 | C8: - | D8: 46204
A9: Actual Timeline | B9: 46199 | C9: -
A11: Total Days | B11: # of Days Spent | C11: Remaining Days | D11: % Ready for Test | E11: % Expected Passed | F11: % Actual Passed
A12: =networkdays(B8, D8, Var!I2:I130) -> 4 | B12: =networkdays(B9, B7, Var!I2:I130) -> 5 | C12: =A12-B12 -> -1 | D12: =B78 -> 1 | E12: =min(1, iferror((A12-C12)/A12, 0)) -> 1 | F12: =E90 -> 0.75
A18: วัตถุประสงค์ของโครงการ
A21: ขอบเขตของโครงการ
A24: Major Issue/Concern
A25: No. | B25: Issue/Concern | C25: Recommendation | D25: Redmine | E25: Status | F25: Responsible By | G25: Target Completion Date | H25: Remark
A26: 1
A27: 2
A28: 3
A29: 4
A31: Test Progress
R36: (ไม่ต้องส่งตารางนี้)
R37: No. of Test Cases | S37: Cancelled | T37: Passed | U37: Passed with Condition | V37: Failed | W37: Pending | X37: In Progress | Y37: Not Start | Z37: Not Ready for Test | AA37: Total Test Cases
R38: %Test Progress | S38: =COUNTIFS('Test Checklist'!$M:$M,S$37) -> 0 | T38: =COUNTIFS('Test Checklist'!$M:$M,T$37) -> 63 | U38: =COUNTIFS('Test Checklist'!$M:$M,U$37) -> 0 | V38: =COUNTIFS('Test Checklist'!$M:$M,V$37) -> 0 | W38: =COUNTIFS('Test Checklist'!$M:$M,W$37) -> 0 | X38: =COUNTIFS('Test Checklist'!$M:$M,X$37) -> 12 | Y38: =COUNTIFS('Test Checklist'!$M:$M,Y$37) -> 0 | Z38: =COUNTIFS('Test Checklist'!$M:$M,Z$37) -> 0 | AA38: =sum(S38:Z38) -> 75
A71: Test Execution Order
R72: (ไม่ต้องส่งตารางนี้)
A73: Test Execution Order | B73: Feature Priority | C73: Test Cases Priority | D73: Test Status | E73: %Progress | F73: %Passed | G73: Plan Start Date | H73: Plan Finish Date | I73: Actual Start Date | J73: Actual Finish Date | R73: Cancelled | S73: Passed | T73: Passed with Condition | U73: Failed | V73: Pending | W73: In Progress | X73: Not Start | Y73: Not Ready for Test | Z73: Total Test Cases
A74: 2 | B74: Feature Priority 1 | C74: Medium | D74: =if(and(E74=0, F74=0),"Not Start", if(and(E74>0,F74<>1),"In Progress", if(and(E74=1,F74=1), "Completed"))) -> Completed | E74: =IFERROR(SUM(R74:W74)/Z74, 0) -> 1 | F74: =IFERROR(SUM(R74:T74)/Z74, 0) -> 1 | G74: 46199 | I74: =IF(MINIFS('Test Checklist'!$O:$O, 'Test Checklist'!$A:$A, $A74)=0, "", MINIFS('Test Checklist'!$O:$O, 'Test Checklist'!$A:$A, $A74)) | J74: =IF(MAXIFS('Test Checklist'!$O:$O, 'Test Checklist'!$A:$A, $A74)=0, "", MAXIFS('Test Checklist'!$O:$O, 'Test Checklist'!$A:$A, $A74)) | R74: =COUNTIFS('Test Checklist'!$K:$K,$B74,'Test Checklist'!$L:$L,$C74,'Test Checklist'!$M:$M,R$73) -> 0 | S74: =COUNTIFS('Test Checklist'!$K:$K,$B74,'Test Checklist'!$L:$L,$C74,'Test Checklist'!$M:$M,S$73) -> 63 | T74: =COUNTIFS('Test Checklist'!$K:$K,$B74,'Test Checklist'!$L:$L,$C74,'Test Checklist'!$M:$M,T$73) -> 0 | U74: =COUNTIFS('Test Checklist'!$K:$K,$B74,'Test Checklist'!$L:$L,$C74,'Test Checklist'!$M:$M,U$73) -> 0 | V74: =COUNTIFS('Test Checklist'!$K:$K,$B74,'Test Checklist'!$L:$L,$C74,'Test Checklist'!$M:$M,V$73) -> 0 | W74: =COUNTIFS('Test Checklist'!$K:$K,$B74,'Test Checklist'!$L:$L,$C74,'Test Checklist'!$M:$M,W$73) -> 0 | X74: =COUNTIFS('Test Checklist'!$K:$K,$B74,'Test Checklist'!$L:$L,$C74,'Test Checklist'!$M:$M,X$73) -> 0 | Y74: =COUNTIFS('Test Checklist'!$K:$K,$B74,'Test Checklist'!$L:$L,$C74,'Test Checklist'!$M:$M,Y$73) -> 0 | Z74: =sum(R74:Y74) -> 63
A76: Ready for Test
A78: Ready for Test | B78: =(counta(C85:C88)-countif(C85:C88, "Not Ready for Test"))/counta(C85:C88) -> 1
A79: Not Ready for Test | B79: =1-B78 -> 0
A81: Test Progress
R82: (ไม่ต้องส่งตารางนี้)
D83: Overall | F83: High | H83: Medium | J83: Low | R83: High | AA83: Medium | AJ83: Low | AS83: Total | BB83: %
A84: Feature | B84: Feature Priority | C84: Test Status | D84: % Test Progress | E84: % Passed | F84: % Test Progress | G84: % Passed | H84: % Test Progress | I84: % Passed | J84: % Test Progress | K84: % Passed | L84: Responsible By | M84: Plan Start Date | N84: Plan Finish Date | O84: Actual Start Date | P84: Actual Finish Date | Q84: Remark | R84: Cancelled | S84: Passed | T84: Passed with Condition | U84: Failed | V84: Pending | W84: In Progress | X84: Not Start | Y84: Not Ready for Test | Z84: Total Test Cases | AA84: Cancelled | AB84: Passed | AC84: Passed with Condition | AD84: Failed | AE84: Pending | AF84: In Progress | AG84: Not Start | AH84: Not Ready for Test | AI84: Total Test Cases | AJ84: Cancelled | AK84: Passed | AL84: Passed with Condition | AM84: Failed | AN84: Pending | AO84: In Progress | AP84: Not Start | AQ84: Not Ready for Test | AR84: Total Test Cases | AS84: Cancelled | AT84: Passed | AU84: Passed with Condition | AV84: Failed | AW84: Pending | AX84: In Progress | AY84: Not Start | AZ84: Not Ready for Test | BA84: Total Test Cases | BB84: Feature | BC84: Cancelled | BD84: Passed | BE84: Passed with Condition | BF84: Failed | BG84: Pending | BH84: In Progress | BI84: Not Start | BJ84: Not Ready for Test | BK84: Total Test Cases
A85: =Var!P2 -> รายการ R05 - Unit Link Products [ULP] Premium Receipt VFA | B85: {=iferror(xlookup(A85, Var!P:P, Var!Q:Q), "")} -> Feature Priority 1 | C85: =IF(E85:E88=1, "Completed", IF(D85:D88="-", "-", IF(D85:D88>0, "In Progress", "Not Start") ) ) -> Completed | D85: =IFERROR(SUM(AS85:AX85)/BA85, "-") -> 1 | E85: =IFERROR(SUM(AS85:AU85)/BA85, "-") -> 1 | F85: =IFERROR(SUM(R85:W85)/Z85, "-") -> - | G85: =IFERROR(SUM(R85:T85)/Z85, "-") -> - | H85: =IFERROR(SUM(AA85:AF85)/AI85, "-") -> 1 | I85: =IFERROR(SUM(AA85:AC85)/AI85, "-") -> 1 | J85: =IFERROR(SUM(AJ85:AO85)/AR85, "-") -> - | K85: =IFERROR(SUM(AJ85:AL85)/AR85, "-") -> - | L85: chutima.so | M85: 46202 | O85: =if(C85<>"Not Start", minifs('Test Checklist'!$O:$O,'Test Checklist'!$D:$D, $A85), "") -> 46203 | P85: =if(C85="Completed", MAXIFS('Test Checklist'!$O:$O, 'Test Checklist'!$D:$D, $A85),"") -> 46205 | R85: =COUNTIFS('Test Checklist'!$D:$D,$A85,'Test Checklist'!$L:$L,$R$83,'Test Checklist'!$M:$M,R$84) -> 0 | S85: =COUNTIFS('Test Checklist'!$D:$D,$A85,'Test Checklist'!$L:$L,$R$83,'Test Checklist'!$M:$M,S$84) -> 0 | T85: =COUNTIFS('Test Checklist'!$D:$D,$A85,'Test Checklist'!$L:$L,$R$83,'Test Checklist'!$M:$M,T$84) -> 0 | U85: =COUNTIFS('Test Checklist'!$D:$D,$A85,'Test Checklist'!$L:$L,$R$83,'Test Checklist'!$M:$M,U$84) -> 0 | V85: =COUNTIFS('Test Checklist'!$D:$D,$A85,'Test Checklist'!$L:$L,$R$83,'Test Checklist'!$M:$M,V$84) -> 0 | W85: =COUNTIFS('Test Checklist'!$D:$D,$A85,'Test Checklist'!$L:$L,$R$83,'Test Checklist'!$M:$M,W$84) -> 0 | X85: =COUNTIFS('Test Checklist'!$D:$D,$A85,'Test Checklist'!$L:$L,$R$83,'Test Checklist'!$M:$M,X$84) -> 0 | Y85: =COUNTIFS('Test Checklist'!$D:$D,$A85,'Test Checklist'!$L:$L,$R$83,'Test Checklist'!$M:$M,Y$84) -> 0 | Z85: =sum(R85:Y85) -> 0 | AA85: =COUNTIFS('Test Checklist'!$D:$D,$A85,'Test Checklist'!$L:$L,$AA$83,'Test Checklist'!$M:$M,AA$84) -> 0 | AB85: =COUNTIFS('Test Checklist'!$D:$D,$A85,'Test Checklist'!$L:$L,$AA$83,'Test Checklist'!$M:$M,AB$84) -> 19 | AC85: =COUNTIFS('Test Checklist'!$D:$D,$A85,'Test Checklist'!$L:$L,$AA$83,'Test Checklist'!$M:$M,AC$84) -> 0 | AD85: =COUNTIFS('Test Checklist'!$D:$D,$A85,'Test Checklist'!$L:$L,$AA$83,'Test Checklist'!$M:$M,AD$84) -> 0 | AE85: =COUNTIFS('Test Checklist'!$D:$D,$A85,'Test Checklist'!$L:$L,$AA$83,'Test Checklist'!$M:$M,AE$84) -> 0 | AF85: =COUNTIFS('Test Checklist'!$D:$D,$A85,'Test Checklist'!$L:$L,$AA$83,'Test Checklist'!$M:$M,AF$84) -> 0 | AG85: =COUNTIFS('Test Checklist'!$D:$D,$A85,'Test Checklist'!$L:$L,$AA$83,'Test Checklist'!$M:$M,AG$84) -> 0 | AH85: =COUNTIFS('Test Checklist'!$D:$D,$A85,'Test Checklist'!$L:$L,$AA$83,'Test Checklist'!$M:$M,AH$84) -> 0 | AI85: =sum(AA85:AH85) -> 19 | AJ85: =COUNTIFS('Test Checklist'!$D:$D,$A85,'Test Checklist'!$L:$L,$AJ$83,'Test Checklist'!$M:$M,AJ$84) -> 0 | AK85: =COUNTIFS('Test Checklist'!$D:$D,$A85,'Test Checklist'!$L:$L,$AJ$83,'Test Checklist'!$M:$M,AK$84) -> 0 | AL85: =COUNTIFS('Test Checklist'!$D:$D,$A85,'Test Checklist'!$L:$L,$AJ$83,'Test Checklist'!$M:$M,AL$84) -> 0 | AM85: =COUNTIFS('Test Checklist'!$D:$D,$A85,'Test Checklist'!$L:$L,$AJ$83,'Test Checklist'!$M:$M,AM$84) -> 0 | AN85: =COUNTIFS('Test Checklist'!$D:$D,$A85,'Test Checklist'!$L:$L,$AJ$83,'Test Checklist'!$M:$M,AN$84) -> 0 | AO85: =COUNTIFS('Test Checklist'!$D:$D,$A85,'Test Checklist'!$L:$L,$AJ$83,'Test Checklist'!$M:$M,AO$84) -> 0 | AP85: =COUNTIFS('Test Checklist'!$D:$D,$A85,'Test Checklist'!$L:$L,$AJ$83,'Test Checklist'!$M:$M,AP$84) -> 0 | AQ85: =COUNTIFS('Test Checklist'!$D:$D,$A85,'Test Checklist'!$L:$L,$AJ$83,'Test Checklist'!$M:$M,AQ$84) -> 0 | AR85: =sum(AJ85:AQ85) -> 0 | AS85: =R85+AA85+AJ85 -> 0 | AT85: =S85+AB85+AK85 -> 19 | AU85: =T85+AC85+AL85 -> 0 | AV85: =U85+AD85+AM85 -> 0 | AW85: =V85+AE85+AN85 -> 0 | AX85: =W85+AF85+AO85 -> 0 | AY85: =X85+AG85+AP85 -> 0 | AZ85: =Y85+AH85+AQ85 -> 0 | BA85: =sum(AS85:AZ85) -> 19 | BB85: =A85 -> รายการ R05 - Unit Link Products [ULP] Premium Receipt VFA | BC85: =iferror(AS85/$BA85, 0) -> 0 | BD85: =iferror(AT85/$BA85, 0) -> 1 | BE85: =iferror(AU85/$BA85, 0) -> 0 | BF85: =iferror(AV85/$BA85, 0) -> 0 | BG85: =iferror(AW85/$BA85, 0) -> 0 | BH85: =iferror(AX85/$BA85, 0) -> 0 | BI85: =iferror(AY85/$BA85, 0) -> 0 | BJ85: =iferror(AZ85/$BA85, 0) -> 0 | BK85: =sum(BC85:BJ85) -> 1
A86: =Var!P3 -> รายการ R06 - Unit Link Products [ULP] Commission override VFA | B86: {=iferror(xlookup(A86, Var!P:P, Var!Q:Q), "")} -> Feature Priority 1 | C86: =IF(E86:E89=1, "Completed", IF(D86:D89="-", "-", IF(D86:D89>0, "In Progress", "Not Start") ) ) -> Completed | D86: =IFERROR(SUM(AS86:AX86)/BA86, "-") -> 1 | E86: =IFERROR(SUM(AS86:AU86)/BA86, "-") -> 1 | F86: =IFERROR(SUM(R86:W86)/Z86, "-") -> - | G86: =IFERROR(SUM(R86:T86)/Z86, "-") -> - | H86: =IFERROR(SUM(AA86:AF86)/AI86, "-") -> 1 | I86: =IFERROR(SUM(AA86:AC86)/AI86, "-") -> 1 | J86: =IFERROR(SUM(AJ86:AO86)/AR86, "-") -> - | K86: =IFERROR(SUM(AJ86:AL86)/AR86, "-") -> - | L86: chutima.so | M86: 46202 | O86: =if(C86<>"Not Start", minifs('Test Checklist'!$O:$O,'Test Checklist'!$D:$D, $A86), "") -> 46205 | P86: =if(C86="Completed", MAXIFS('Test Checklist'!$O:$O, 'Test Checklist'!$D:$D, $A86),"") -> 46205 | R86: =COUNTIFS('Test Checklist'!$D:$D,$A86,'Test Checklist'!$L:$L,$R$83,'Test Checklist'!$M:$M,R$84) -> 0 | S86: =COUNTIFS('Test Checklist'!$D:$D,$A86,'Test Checklist'!$L:$L,$R$83,'Test Checklist'!$M:$M,S$84) -> 0 | T86: =COUNTIFS('Test Checklist'!$D:$D,$A86,'Test Checklist'!$L:$L,$R$83,'Test Checklist'!$M:$M,T$84) -> 0 | U86: =COUNTIFS('Test Checklist'!$D:$D,$A86,'Test Checklist'!$L:$L,$R$83,'Test Checklist'!$M:$M,U$84) -> 0 | V86: =COUNTIFS('Test Checklist'!$D:$D,$A86,'Test Checklist'!$L:$L,$R$83,'Test Checklist'!$M:$M,V$84) -> 0 | W86: =COUNTIFS('Test Checklist'!$D:$D,$A86,'Test Checklist'!$L:$L,$R$83,'Test Checklist'!$M:$M,W$84) -> 0 | X86: =COUNTIFS('Test Checklist'!$D:$D,$A86,'Test Checklist'!$L:$L,$R$83,'Test Checklist'!$M:$M,X$84) -> 0 | Y86: =COUNTIFS('Test Checklist'!$D:$D,$A86,'Test Checklist'!$L:$L,$R$83,'Test Checklist'!$M:$M,Y$84) -> 0 | Z86: =sum(R86:Y86) -> 0 | AA86: =COUNTIFS('Test Checklist'!$D:$D,$A86,'Test Checklist'!$L:$L,$AA$83,'Test Checklist'!$M:$M,AA$84) -> 0 | AB86: =COUNTIFS('Test Checklist'!$D:$D,$A86,'Test Checklist'!$L:$L,$AA$83,'Test Checklist'!$M:$M,AB$84) -> 23 | AC86: =COUNTIFS('Test Checklist'!$D:$D,$A86,'Test Checklist'!$L:$L,$AA$83,'Test Checklist'!$M:$M,AC$84) -> 0 | AD86: =COUNTIFS('Test Checklist'!$D:$D,$A86,'Test Checklist'!$L:$L,$AA$83,'Test Checklist'!$M:$M,AD$84) -> 0 | AE86: =COUNTIFS('Test Checklist'!$D:$D,$A86,'Test Checklist'!$L:$L,$AA$83,'Test Checklist'!$M:$M,AE$84) -> 0 | AF86: =COUNTIFS('Test Checklist'!$D:$D,$A86,'Test Checklist'!$L:$L,$AA$83,'Test Checklist'!$M:$M,AF$84) -> 0 | AG86: =COUNTIFS('Test Checklist'!$D:$D,$A86,'Test Checklist'!$L:$L,$AA$83,'Test Checklist'!$M:$M,AG$84) -> 0 | AH86: =COUNTIFS('Test Checklist'!$D:$D,$A86,'Test Checklist'!$L:$L,$AA$83,'Test Checklist'!$M:$M,AH$84) -> 0 | AI86: =sum(AA86:AH86) -> 23 | AJ86: =COUNTIFS('Test Checklist'!$D:$D,$A86,'Test Checklist'!$L:$L,$AJ$83,'Test Checklist'!$M:$M,AJ$84) -> 0 | AK86: =COUNTIFS('Test Checklist'!$D:$D,$A86,'Test Checklist'!$L:$L,$AJ$83,'Test Checklist'!$M:$M,AK$84) -> 0 | AL86: =COUNTIFS('Test Checklist'!$D:$D,$A86,'Test Checklist'!$L:$L,$AJ$83,'Test Checklist'!$M:$M,AL$84) -> 0 | AM86: =COUNTIFS('Test Checklist'!$D:$D,$A86,'Test Checklist'!$L:$L,$AJ$83,'Test Checklist'!$M:$M,AM$84) -> 0 | AN86: =COUNTIFS('Test Checklist'!$D:$D,$A86,'Test Checklist'!$L:$L,$AJ$83,'Test Checklist'!$M:$M,AN$84) -> 0 | AO86: =COUNTIFS('Test Checklist'!$D:$D,$A86,'Test Checklist'!$L:$L,$AJ$83,'Test Checklist'!$M:$M,AO$84) -> 0 | AP86: =COUNTIFS('Test Checklist'!$D:$D,$A86,'Test Checklist'!$L:$L,$AJ$83,'Test Checklist'!$M:$M,AP$84) -> 0 | AQ86: =COUNTIFS('Test Checklist'!$D:$D,$A86,'Test Checklist'!$L:$L,$AJ$83,'Test Checklist'!$M:$M,AQ$84) -> 0 | AR86: =sum(AJ86:AQ86) -> 0 | AS86: =R86+AA86+AJ86 -> 0 | AT86: =S86+AB86+AK86 -> 23 | AU86: =T86+AC86+AL86 -> 0 | AV86: =U86+AD86+AM86 -> 0 | AW86: =V86+AE86+AN86 -> 0 | AX86: =W86+AF86+AO86 -> 0 | AY86: =X86+AG86+AP86 -> 0 | AZ86: =Y86+AH86+AQ86 -> 0 | BA86: =sum(AS86:AZ86) -> 23 | BB86: =A86 -> รายการ R06 - Unit Link Products [ULP] Commission override VFA | BC86: =iferror(AS86/$BA86, 0) -> 0 | BD86: =iferror(AT86/$BA86, 0) -> 1 | BE86: =iferror(AU86/$BA86, 0) -> 0 | BF86: =iferror(AV86/$BA86, 0) -> 0 | BG86: =iferror(AW86/$BA86, 0) -> 0 | BH86: =iferror(AX86/$BA86, 0) -> 0 | BI86: =iferror(AY86/$BA86, 0) -> 0 | BJ86: =iferror(AZ86/$BA86, 0) -> 0 | BK86: =sum(BC86:BJ86) -> 1
A87: =Var!P4 -> รายการ R02 - Ordinary Products [OP] Commission override GMM | B87: {=iferror(xlookup(A87, Var!P:P, Var!Q:Q), "")} -> Feature Priority 1 | C87: =IF(E87:E90=1, "Completed", IF(D87:D90="-", "-", IF(D87:D90>0, "In Progress", "Not Start") ) ) -> Completed | D87: =IFERROR(SUM(AS87:AX87)/BA87, "-") -> 1 | E87: =IFERROR(SUM(AS87:AU87)/BA87, "-") -> 1 | F87: =IFERROR(SUM(R87:W87)/Z87, "-") -> - | G87: =IFERROR(SUM(R87:T87)/Z87, "-") -> - | H87: =IFERROR(SUM(AA87:AF87)/AI87, "-") -> 1 | I87: =IFERROR(SUM(AA87:AC87)/AI87, "-") -> 1 | J87: =IFERROR(SUM(AJ87:AO87)/AR87, "-") -> - | K87: =IFERROR(SUM(AJ87:AL87)/AR87, "-") -> - | L87: chutima.so | M87: 46199 | O87: =if(C87<>"Not Start", minifs('Test Checklist'!$O:$O,'Test Checklist'!$D:$D, $A87), "") -> 46199 | P87: =if(C87="Completed", MAXIFS('Test Checklist'!$O:$O, 'Test Checklist'!$D:$D, $A87),"") -> 46202 | R87: =COUNTIFS('Test Checklist'!$D:$D,$A87,'Test Checklist'!$L:$L,$R$83,'Test Checklist'!$M:$M,R$84) -> 0 | S87: =COUNTIFS('Test Checklist'!$D:$D,$A87,'Test Checklist'!$L:$L,$R$83,'Test Checklist'!$M:$M,S$84) -> 0 | T87: =COUNTIFS('Test Checklist'!$D:$D,$A87,'Test Checklist'!$L:$L,$R$83,'Test Checklist'!$M:$M,T$84) -> 0 | U87: =COUNTIFS('Test Checklist'!$D:$D,$A87,'Test Checklist'!$L:$L,$R$83,'Test Checklist'!$M:$M,U$84) -> 0 | V87: =COUNTIFS('Test Checklist'!$D:$D,$A87,'Test Checklist'!$L:$L,$R$83,'Test Checklist'!$M:$M,V$84) -> 0 | W87: =COUNTIFS('Test Checklist'!$D:$D,$A87,'Test Checklist'!$L:$L,$R$83,'Test Checklist'!$M:$M,W$84) -> 0 | X87: =COUNTIFS('Test Checklist'!$D:$D,$A87,'Test Checklist'!$L:$L,$R$83,'Test Checklist'!$M:$M,X$84) -> 0 | Y87: =COUNTIFS('Test Checklist'!$D:$D,$A87,'Test Checklist'!$L:$L,$R$83,'Test Checklist'!$M:$M,Y$84) -> 0 | Z87: =sum(R87:Y87) -> 0 | AA87: =COUNTIFS('Test Checklist'!$D:$D,$A87,'Test Checklist'!$L:$L,$AA$83,'Test Checklist'!$M:$M,AA$84) -> 0 | AB87: =COUNTIFS('Test Checklist'!$D:$D,$A87,'Test Checklist'!$L:$L,$AA$83,'Test Checklist'!$M:$M,AB$84) -> 21 | AC87: =COUNTIFS('Test Checklist'!$D:$D,$A87,'Test Checklist'!$L:$L,$AA$83,'Test Checklist'!$M:$M,AC$84) -> 0 | AD87: =COUNTIFS('Test Checklist'!$D:$D,$A87,'Test Checklist'!$L:$L,$AA$83,'Test Checklist'!$M:$M,AD$84) -> 0 | AE87: =COUNTIFS('Test Checklist'!$D:$D,$A87,'Test Checklist'!$L:$L,$AA$83,'Test Checklist'!$M:$M,AE$84) -> 0 | AF87: =COUNTIFS('Test Checklist'!$D:$D,$A87,'Test Checklist'!$L:$L,$AA$83,'Test Checklist'!$M:$M,AF$84) -> 0 | AG87: =COUNTIFS('Test Checklist'!$D:$D,$A87,'Test Checklist'!$L:$L,$AA$83,'Test Checklist'!$M:$M,AG$84) -> 0 | AH87: =COUNTIFS('Test Checklist'!$D:$D,$A87,'Test Checklist'!$L:$L,$AA$83,'Test Checklist'!$M:$M,AH$84) -> 0 | AI87: =sum(AA87:AH87) -> 21 | AJ87: =COUNTIFS('Test Checklist'!$D:$D,$A87,'Test Checklist'!$L:$L,$AJ$83,'Test Checklist'!$M:$M,AJ$84) -> 0 | AK87: =COUNTIFS('Test Checklist'!$D:$D,$A87,'Test Checklist'!$L:$L,$AJ$83,'Test Checklist'!$M:$M,AK$84) -> 0 | AL87: =COUNTIFS('Test Checklist'!$D:$D,$A87,'Test Checklist'!$L:$L,$AJ$83,'Test Checklist'!$M:$M,AL$84) -> 0 | AM87: =COUNTIFS('Test Checklist'!$D:$D,$A87,'Test Checklist'!$L:$L,$AJ$83,'Test Checklist'!$M:$M,AM$84) -> 0 | AN87: =COUNTIFS('Test Checklist'!$D:$D,$A87,'Test Checklist'!$L:$L,$AJ$83,'Test Checklist'!$M:$M,AN$84) -> 0 | AO87: =COUNTIFS('Test Checklist'!$D:$D,$A87,'Test Checklist'!$L:$L,$AJ$83,'Test Checklist'!$M:$M,AO$84) -> 0 | AP87: =COUNTIFS('Test Checklist'!$D:$D,$A87,'Test Checklist'!$L:$L,$AJ$83,'Test Checklist'!$M:$M,AP$84) -> 0 | AQ87: =COUNTIFS('Test Checklist'!$D:$D,$A87,'Test Checklist'!$L:$L,$AJ$83,'Test Checklist'!$M:$M,AQ$84) -> 0 | AR87: =sum(AJ87:AQ87) -> 0 | AS87: =R87+AA87+AJ87 -> 0 | AT87: =S87+AB87+AK87 -> 21 | AU87: =T87+AC87+AL87 -> 0 | AV87: =U87+AD87+AM87 -> 0 | AW87: =V87+AE87+AN87 -> 0 | AX87: =W87+AF87+AO87 -> 0 | AY87: =X87+AG87+AP87 -> 0 | AZ87: =Y87+AH87+AQ87 -> 0 | BA87: =sum(AS87:AZ87) -> 21 | BB87: =A87 -> รายการ R02 - Ordinary Products [OP] Commission override GMM | BC87: =iferror(AS87/$BA87, 0) -> 0 | BD87: =iferror(AT87/$BA87, 0) -> 1 | BE87: =iferror(AU87/$BA87, 0) -> 0 | BF87: =iferror(AV87/$BA87, 0) -> 0 | BG87: =iferror(AW87/$BA87, 0) -> 0 | BH87: =iferror(AX87/$BA87, 0) -> 0 | BI87: =iferror(AY87/$BA87, 0) -> 0 | BJ87: =iferror(AZ87/$BA87, 0) -> 0 | BK87: =sum(BC87:BJ87) -> 1
A88: =Var!P5 -> รายการ R14 - Ordinary Products [OP] APL and PL GMM | B88: {=iferror(xlookup(A88, Var!P:P, Var!Q:Q), "")} -> Feature Priority 1 | C88: =IF(E88:E91=1, "Completed", IF(D88:D91="-", "-", IF(D88:D91>0, "In Progress", "Not Start") ) ) -> In Progress | D88: =IFERROR(SUM(AS88:AX88)/BA88, "-") -> 1 | E88: =IFERROR(SUM(AS88:AU88)/BA88, "-") -> 0 | F88: =IFERROR(SUM(R88:W88)/Z88, "-") -> - | G88: =IFERROR(SUM(R88:T88)/Z88, "-") -> - | H88: =IFERROR(SUM(AA88:AF88)/AI88, "-") -> 1 | I88: =IFERROR(SUM(AA88:AC88)/AI88, "-") -> 0 | J88: =IFERROR(SUM(AJ88:AO88)/AR88, "-") -> - | K88: =IFERROR(SUM(AJ88:AL88)/AR88, "-") -> - | L88: chutima.so | M88: 46212 | O88: =if(C88<>"Not Start", minifs('Test Checklist'!$O:$O,'Test Checklist'!$D:$D, $A88), "") -> 46205 | P88: =if(C88="Completed", MAXIFS('Test Checklist'!$O:$O, 'Test Checklist'!$D:$D, $A88),"") | R88: =COUNTIFS('Test Checklist'!$D:$D,$A88,'Test Checklist'!$L:$L,$R$83,'Test Checklist'!$M:$M,R$84) -> 0 | S88: =COUNTIFS('Test Checklist'!$D:$D,$A88,'Test Checklist'!$L:$L,$R$83,'Test Checklist'!$M:$M,S$84) -> 0 | T88: =COUNTIFS('Test Checklist'!$D:$D,$A88,'Test Checklist'!$L:$L,$R$83,'Test Checklist'!$M:$M,T$84) -> 0 | U88: =COUNTIFS('Test Checklist'!$D:$D,$A88,'Test Checklist'!$L:$L,$R$83,'Test Checklist'!$M:$M,U$84) -> 0 | V88: =COUNTIFS('Test Checklist'!$D:$D,$A88,'Test Checklist'!$L:$L,$R$83,'Test Checklist'!$M:$M,V$84) -> 0 | W88: =COUNTIFS('Test Checklist'!$D:$D,$A88,'Test Checklist'!$L:$L,$R$83,'Test Checklist'!$M:$M,W$84) -> 0 | X88: =COUNTIFS('Test Checklist'!$D:$D,$A88,'Test Checklist'!$L:$L,$R$83,'Test Checklist'!$M:$M,X$84) -> 0 | Y88: =COUNTIFS('Test Checklist'!$D:$D,$A88,'Test Checklist'!$L:$L,$R$83,'Test Checklist'!$M:$M,Y$84) -> 0 | Z88: =sum(R88:Y88) -> 0 | AA88: =COUNTIFS('Test Checklist'!$D:$D,$A88,'Test Checklist'!$L:$L,$AA$83,'Test Checklist'!$M:$M,AA$84) -> 0 | AB88: =COUNTIFS('Test Checklist'!$D:$D,$A88,'Test Checklist'!$L:$L,$AA$83,'Test Checklist'!$M:$M,AB$84) -> 0 | AC88: =COUNTIFS('Test Checklist'!$D:$D,$A88,'Test Checklist'!$L:$L,$AA$83,'Test Checklist'!$M:$M,AC$84) -> 0 | AD88: =COUNTIFS('Test Checklist'!$D:$D,$A88,'Test Checklist'!$L:$L,$AA$83,'Test Checklist'!$M:$M,AD$84) -> 0 | AE88: =COUNTIFS('Test Checklist'!$D:$D,$A88,'Test Checklist'!$L:$L,$AA$83,'Test Checklist'!$M:$M,AE$84) -> 0 | AF88: =COUNTIFS('Test Checklist'!$D:$D,$A88,'Test Checklist'!$L:$L,$AA$83,'Test Checklist'!$M:$M,AF$84) -> 12 | AG88: =COUNTIFS('Test Checklist'!$D:$D,$A88,'Test Checklist'!$L:$L,$AA$83,'Test Checklist'!$M:$M,AG$84) -> 0 | AH88: =COUNTIFS('Test Checklist'!$D:$D,$A88,'Test Checklist'!$L:$L,$AA$83,'Test Checklist'!$M:$M,AH$84) -> 0 | AI88: =sum(AA88:AH88) -> 12 | AJ88: =COUNTIFS('Test Checklist'!$D:$D,$A88,'Test Checklist'!$L:$L,$AJ$83,'Test Checklist'!$M:$M,AJ$84) -> 0 | AK88: =COUNTIFS('Test Checklist'!$D:$D,$A88,'Test Checklist'!$L:$L,$AJ$83,'Test Checklist'!$M:$M,AK$84) -> 0 | AL88: =COUNTIFS('Test Checklist'!$D:$D,$A88,'Test Checklist'!$L:$L,$AJ$83,'Test Checklist'!$M:$M,AL$84) -> 0 | AM88: =COUNTIFS('Test Checklist'!$D:$D,$A88,'Test Checklist'!$L:$L,$AJ$83,'Test Checklist'!$M:$M,AM$84) -> 0 | AN88: =COUNTIFS('Test Checklist'!$D:$D,$A88,'Test Checklist'!$L:$L,$AJ$83,'Test Checklist'!$M:$M,AN$84) -> 0 | AO88: =COUNTIFS('Test Checklist'!$D:$D,$A88,'Test Checklist'!$L:$L,$AJ$83,'Test Checklist'!$M:$M,AO$84) -> 0 | AP88: =COUNTIFS('Test Checklist'!$D:$D,$A88,'Test Checklist'!$L:$L,$AJ$83,'Test Checklist'!$M:$M,AP$84) -> 0 | AQ88: =COUNTIFS('Test Checklist'!$D:$D,$A88,'Test Checklist'!$L:$L,$AJ$83,'Test Checklist'!$M:$M,AQ$84) -> 0 | AR88: =sum(AJ88:AQ88) -> 0 | AS88: =R88+AA88+AJ88 -> 0 | AT88: =S88+AB88+AK88 -> 0 | AU88: =T88+AC88+AL88 -> 0 | AV88: =U88+AD88+AM88 -> 0 | AW88: =V88+AE88+AN88 -> 0 | AX88: =W88+AF88+AO88 -> 12 | AY88: =X88+AG88+AP88 -> 0 | AZ88: =Y88+AH88+AQ88 -> 0 | BA88: =sum(AS88:AZ88) -> 12 | BB88: =A88 -> รายการ R14 - Ordinary Products [OP] APL and PL GMM | BC88: =iferror(AS88/$BA88, 0) -> 0 | BD88: =iferror(AT88/$BA88, 0) -> 0 | BE88: =iferror(AU88/$BA88, 0) -> 0 | BF88: =iferror(AV88/$BA88, 0) -> 0 | BG88: =iferror(AW88/$BA88, 0) -> 0 | BH88: =iferror(AX88/$BA88, 0) -> 1 | BI88: =iferror(AY88/$BA88, 0) -> 0 | BJ88: =iferror(AZ88/$BA88, 0) -> 0 | BK88: =sum(BC88:BJ88) -> 1
A89: %Test Progress (Ready for Test) | D89: =iferror(average(D85:D88), 0) -> 1 | E89: =iferror(average(E85:E88), 0) -> 0.75 | F89: =iferror(average(F85:F88), 0) -> 0 | G89: =iferror(average(G85:G88), 0) -> 0 | H89: =iferror(average(H85:H88), 0) -> 1 | I89: =iferror(average(I85:I88), 0) -> 0.75 | J89: =iferror(average(J85:J88), 0) -> 0 | K89: =iferror(average(K85:K88), 0) -> 0 | R89: =subtotal(9,R85:R88) -> 0 | S89: =subtotal(9,S85:S88) -> 0 | T89: =subtotal(9,T85:T88) -> 0 | U89: =subtotal(9,U85:U88) -> 0 | V89: =subtotal(9,V85:V88) -> 0 | W89: =subtotal(9,W85:W88) -> 0 | X89: =subtotal(9,X85:X88) -> 0 | Y89: =subtotal(9,Y85:Y88) -> 0 | Z89: =sum(R89:Y89) -> 0 | AA89: =subtotal(9,AA85:AA88) -> 0 | AB89: =subtotal(9,AB85:AB88) -> 63 | AC89: =subtotal(9,AC85:AC88) -> 0 | AD89: =subtotal(9,AD85:AD88) -> 0 | AE89: =subtotal(9,AE85:AE88) -> 0 | AF89: =subtotal(9,AF85:AF88) -> 12 | AG89: =subtotal(9,AG85:AG88) -> 0 | AH89: =subtotal(9,AH85:AH88) -> 0 | AI89: =sum(AA89:AH89) -> 75 | AJ89: =subtotal(9,AJ85:AJ88) -> 0 | AK89: =subtotal(9,AK85:AK88) -> 0 | AL89: =subtotal(9,AL85:AL88) -> 0 | AM89: =subtotal(9,AM85:AM88) -> 0 | AN89: =subtotal(9,AN85:AN88) -> 0 | AO89: =subtotal(9,AO85:AO88) -> 0 | AP89: =subtotal(9,AP85:AP88) -> 0 | AQ89: =subtotal(9,AQ85:AQ88) -> 0 | AR89: =sum(AJ89:AQ89) -> 0 | AS89: =subtotal(9,AS85:AS88) -> 0 | AT89: =subtotal(9,AT85:AT88) -> 63 | AU89: =subtotal(9,AU85:AU88) -> 0 | AV89: =subtotal(9,AV85:AV88) -> 0 | AW89: =subtotal(9,AW85:AW88) -> 0 | AX89: =subtotal(9,AX85:AX88) -> 12 | AY89: =subtotal(9,AY85:AY88) -> 0 | AZ89: =subtotal(9,AZ85:AZ88) -> 0 | BA89: =sum(AS89:AZ89) -> 75 | BC89: =AS89/$BA89 -> 0 | BD89: =AT89/$BA89 -> 0.84 | BE89: =AU89/$BA89 -> 0 | BF89: =AV89/$BA89 -> 0 | BG89: =AW89/$BA89 -> 0 | BH89: =AX89/$BA89 -> 0.16 | BI89: =AY89/$BA89 -> 0 | BJ89: =AZ89/$BA89 -> 0 | BK89: =sum(BC89:BJ89) -> 1
A90: %Test Progress (Overall) | D90: =iferror(average(D85:D88)*$B$78, 0) -> 1 | E90: =iferror(average(E85:E88)*$B$78, 0) -> 0.75 | F90: =iferror(average(F85:F88)*$B$78, 0) -> 0 | G90: =iferror(average(G85:G88)*$B$78, 0) -> 0 | H90: =iferror(average(H85:H88)*$B$78, 0) -> 1 | I90: =iferror(average(I85:I88)*$B$78, 0) -> 0.75 | J90: =iferror(average(J85:J88)*$B$78, 0) -> 0 | K90: =iferror(average(K85:K88)*$B$78, 0) -> 0
A92: Issue Summary
...

Sheet Test Plan
A1: Test Plan
A3: Reference
A5: No. | B5: Reference | C5: Remark
A6: 1 | B6: Project Charter
A7: 2 | B7: Project Estimation
A8: 3 | B8: Business Requirement Document (BRD)
A9: 4 | B9: Business Workflow
A10: 5 | B10: Business Scenario
A11: 6 | B11: Business Requirements อื่นๆ เช่น ข้อกำหนดการขาย, ระเบียบ ฯลฯ
A12: 7 | B12: Requirement Traceability Matrix (RTM)
A13: 8 | B13: Product Architecture (PA)
A14: 9 | B14: Software Requirements Specification (SRS)
A15: 10 | B15: Functional Requirement Document (FSD)
A16: 11 | B16: Technical Specification Document (TSD)
A17: 12 | B17: Data Migration Strategy (ถ้ามี)
A18: 13 | B18: Cost Analysis (CA)
A19: 14 | B19: Project Plan | C19: https://redmine.ochi.link/
A20: 15
A21: 16
A23: Assumption
A25: No. | B25: Assumption
A26: 1
A27: 2
A28: 3
A30: In Scopes of Testing
A32: No. | B32: In Scopes of Testing
A33: 1
A34: 2
A35: 3
A36: 4
A37: 5
A39: Out Scopes of Testing
A41: No. | B41: Out Scopes of Testing
A42: 1
A43: 2 | B43: ส่วนอื่นๆ ที่ไม่อยู่ใน In Scopes of Testing
A45: Impact/Related System
A47: No. | B47: System | C47: Impacted/Related System
A48: 1
A49: 2
A51: Test Device
...

Sheet Timeline

Sheet Test Checklist
A1: Test Checklist
A3: Test Execution Order | B3: Test Checklist ID | C3: Application | D3: Feature * | E3: Test Case Type * | F3: Test Objective | G3: Test Condition | H3: Test Step | I3: Expected Results | J3: Test Data | K3: Feature Priority | L3: Test Case Priority | M3: Test Status * | N3: Tested By | O3: Tested Date | P3: Redmine No. | Q3: Remark
B4: รายการ R05 - Unit Link Products [ULP] Premium Receipt VFA | F4: Process การประมวลผลข้อมูลออกรายงาน R05
B5: รายงาน R05ACC (ฝ่ายบัญชี)
B6: TC-R05-01 | C6: Enterprise Data Warehouse | D6: รายการ R05 - Unit Link Products [ULP] Premium Receipt VFA | E6: Functional (Happy Path) | F6: ตรวจสอบ เพิ่มการดึง GL Code ของรายงาน R05ACC - 14011000 : เบี้ยประกันชีวิตค้างรับ - 14012000 : เบี้ยประกันอุบัติเหตุค้างรับ - 14013000 : เบี้ยประกันสุขภาพค้างรับ - 21540005 : เบี้ยประกันชีวิตรับล่วงหน้า - 21540010 : เบี้ยประกันอุบัติเหตุรับล่วงหน้า - 21540015 : เบี้ยประกันสุขภาพรับล่วงหน้า - 21540006 : ส่วนลดเบี้ยประกันชีวิตล่วงหน้า | H6: 1. Log in เข้าระบบ NBS : acc1 2. เลือกเมนู : ระบบงาน Back Office > ระบบ Enterprise Data Warehouse > ระบบ Enterprise Data Warehouse 3. เลือกเมนู : Reconcile Data > ปรับปรุงรายการทางบัญชี -> ระบุเงื่อนไขการประมวลผล -> กดปุ่ม ประมวลผล | I6: 1. รายงาน R05ACC : แสดงข้อมูล บัญชี และดึงข้อมูล GL Code มาแสดงครบถ้วนถูกต้อง - 14011000 : เบี้ยประกันชีวิตค้างรับ - 14012000 : เบี้ยประกันอุบัติเหตุค้างรับ - 14013000 : เบี้ยประกันสุขภาพค้างรับ - 21540005 : เบี้ยประกันชีวิตรับล่วงหน้า - 21540010 : เบี้ยประกันอุบัติเหตุรับล่วงหน้า - 21540015 : เบี้ยประกันสุขภาพรับล่วงหน้า - 21540006 : ส่วนลดเบี้ยประกันชีวิตล่วงหน้า | K6: {=IF(D6="", "", IFERROR(XLOOKUP(D6, Var!$P:$P, Var!$Q:$Q), ""))} -> Feature Priority 1 | L6: Medium | M6: Passed | N6: chutima.so | O6: 46204 | Q6: ผลทดสอบ SIT Result : UR 20260040 Improvement for OIC timeline (ปรับปรุง R- Report) Note SA น้องจูน ทดสอบได้แค่ GL Code : 14011000 เพราะ GL Code : 14012000, 14013000, 21540005, 21540010, 21540015, 21540006 ยังไม่มี set ในผังค่ะ
B7: TC-R05-02 | C7: Enterprise Data Warehouse | D7: รายการ R05 - Unit Link Products [ULP] Premium Receipt VFA | E7: Functional (Happy Path) | F7: ตรวจสอบ การแสดงข้อมูล GL Code หมวด 4 ที่ผูกกับ EventCode : ML-0009 และ ML-0010 และ GL 14011000 ของรายงาน R05ACC EventCode ML-0009 - 14011000 : เบี้ยประกันชีวิตค้างรับ - 40511100 : เบี้ยประกันชีวิต - ปีแรก (Premium Charge) - 40511200 : เบี้ยประกันชีวิต - ปีต่อไป (Premium Charge) - 40511500 : เบี้ยส่วนนำไปลงทุนของผู้เอาประกัน EventCode ML-0010 - 14011000 : เบี้ยประกันชีวิตค้างรับ - 40511100 : เบี้ยประกันชีวิต - ปีแรก (Premium Charge) - 40511200 : เบี้ยประกันชีวิต - ปีต่อไป (Premium Charge) - 40511500 : เบี้ยส่วนนำไปลงทุนของผู้เอาประกัน - 40512100 : เบี้ยประกันอุบัติเหตุ - ปีแรก (Phase 2) (รายการนี้ยังไม่มีใน UL) - 40512200 : เบี้ยประกันอุบัติเหตุ - ปีต่อไป (Phase 2) (รายการนี้ยังไม่มีใน UL) - 40513100 : เบี้ยประกันสุขภาพ - ปีแรก (Phase 2) (รายการนี้ยังไม่มีใน UL) - 40513200 : เบี้ยประกันสุขภาพ - ปีต่อไป (Phase 2) (รายการนี้ยังไม่มีใน UL) | I7: 1. รายงาน R05ACC : แสดงข้อมูล บัญชี ของ ข้อมูล GL Code หมวด 4 ที่ผูกกับ EventCode : ML-0009 และ ML-0010 และ GL 14011000 ถูกต้องครบถ้วน EventCode ML-0009 - 14011000 : เบี้ยประกันชีวิตค้างรับ - 40511100 : เบี้ยประกันชีวิต - ปีแรก (Premium Charge) - 40511200 : เบี้ยประกันชีวิต - ปีต่อไป (Premium Charge) - 40511500 : เบี้ยส่วนนำไปลงทุนของผู้เอาประกัน EventCode ML-0010 - 14011000 : เบี้ยประกันชีวิตค้างรับ - 40511100 : เบี้ยประกันชีวิต - ปีแรก (Premium Charge) - 40511200 : เบี้ยประกันชีวิต - ปีต่อไป (Premium Charge) - 40511500 : เบี้ยส่วนนำไปลงทุนของผู้เอาประกัน - 40512100 : เบี้ยประกันอุบัติเหตุ - ปีแรก (Phase 2) (รายการนี้ยังไม่มีใน UL) - 40512200 : เบี้ยประกันอุบัติเหตุ - ปีต่อไป (Phase 2) (รายการนี้ยังไม่มีใน UL) - 40513100 : เบี้ยประกันสุขภาพ - ปีแรก (Phase 2) (รายการนี้ยังไม่มีใน UL) - 40513200 : เบี้ยประกันสุขภาพ - ปีต่อไป (Phase 2) (รายการนี้ยังไม่มีใน UL) | K7: {=IF(D7="", "", IFERROR(XLOOKUP(D7, Var!$P:$P, Var!$Q:$Q), ""))} -> Feature Priority 1 | L7: Medium | M7: Passed | N7: chutima.so | O7: 46204
B8: TC-R05-03 | C8: Enterprise Data Warehouse | D8: รายการ R05 - Unit Link Products [ULP] Premium Receipt VFA | E8: Functional (Happy Path) | F8: ตรวจสอบการแสดง Receive Payment Type ของรายงาน R05ACC | G8: Sheet :Reconcile Actual DATA | H8: Path วางไฟล์รายงาน R \\10.40.24.246\edw\UAT\IFRS17\Report R | I8: 1. รายงาน R05ACC : Sheet Reconcile Actual DATA - แสดง Column Receive Payment Type - มีการ Grouping Column เพิ่ม field Receive Payment Type | K8: {=IF(D8="", "", IFERROR(XLOOKUP(D8, Var!$P:$P, Var!$Q:$Q), ""))} -> Feature Priority 1 | L8: Medium | M8: Passed | N8: chutima.so | O8: 46204
B9: TC-R05-04 | C9: Enterprise Data Warehouse | D9: รายการ R05 - Unit Link Products [ULP] Premium Receipt VFA | E9: Functional (Happy Path) | G9: Sheet : Adjustment Posting | H9: Path วางไฟล์รายงาน R \\10.40.24.246\edw\UAT\IFRS17\Report R | I9: 1. รายงาน R05ACC : Sheet Adjustment Posting - แสดง Column Receive Payment Type - มีการ Grouping Column เพิ่ม field Receive Payment Type | K9: {=IF(D9="", "", IFERROR(XLOOKUP(D9, Var!$P:$P, Var!$Q:$Q), ""))} -> Feature Priority 1 | L9: Medium | M9: Passed | N9: chutima.so | O9: 46204
B10: TC-R05-05 | C10: Enterprise Data Warehouse | D10: รายการ R05 - Unit Link Products [ULP] Premium Receipt VFA | E10: Functional (Happy Path) | F10: ตรวจสอบการแสดง Disclosure Type ของรายงาน R05ACC กรณี GL Code เท่ากับ 14011000 , 14012000 , 14013000, 21540005, 21540010, 21540015 , 21540006 | G10: Sheet :Reconcile Actual DATA | H10: Path วางไฟล์รายงาน R \\10.40.24.246\edw\UAT\IFRS17\Report R | I10: 1. รายงาน R05ACC : Sheet Reconcile Actual DATA - แสดง Disclosure Type แสดงเป็นค่าว่าง | K10: {=IF(D10="", "", IFERROR(XLOOKUP(D10, Var!$P:$P, Var!$Q:$Q), ""))} -> Feature Priority 1 | L10: Medium | M10: Passed | N10: chutima.so | O10: 46204
B11: TC-R05-06 | C11: Enterprise Data Warehouse | D11: รายการ R05 - Unit Link Products [ULP] Premium Receipt VFA | E11: Functional (Happy Path) | G11: Sheet : Adjustment Posting | H11: Path วางไฟล์รายงาน R \\10.40.24.246\edw\UAT\IFRS17\Report R | I11: 1. รายงาน R05ACC : Sheet Adjustment Posting - แสดง Disclosure Type แสดงเป็นค่าว่าง | K11: {=IF(D11="", "", IFERROR(XLOOKUP(D11, Var!$P:$P, Var!$Q:$Q), ""))} -> Feature Priority 1 | L11: Medium | M11: Passed | N11: chutima.so | O11: 46204
B12: TC-R05-07 | C12: Enterprise Data Warehouse | D12: รายการ R05 - Unit Link Products [ULP] Premium Receipt VFA | E12: Functional (Happy Path) | F12: ตรวจสอบการแสดง Plan Code ของรายงาน R05ACC กรณี GL Code เท่ากับ 14011000 , 14012000 , 14013000, 21540005, 21540010, 21540015 , 21540006 | G12: Sheet :Reconcile Actual DATA | H12: Path วางไฟล์รายงาน R \\10.40.24.246\edw\UAT\IFRS17\Report R | I12: 1. รายงาน R05ACC : Sheet Reconcile Actual DATA - แสดง Plan Code แสดงเป็นค่าว่าง | K12: {=IF(D12="", "", IFERROR(XLOOKUP(D12, Var!$P:$P, Var!$Q:$Q), ""))} -> Feature Priority 1 | L12: Medium | M12: Passed | N12: chutima.so | O12: 46204
B13: TC-R05-08 | C13: Enterprise Data Warehouse | D13: รายการ R05 - Unit Link Products [ULP] Premium Receipt VFA | E13: Functional (Happy Path) | G13: Sheet : Adjustment Posting | H13: Path วางไฟล์รายงาน R \\10.40.24.246\edw\UAT\IFRS17\Report R | I13: 1. รายงาน R05ACC : Sheet Adjustment Posting - แสดง Plan Code แสดงเป็นค่าว่าง | K13: {=IF(D13="", "", IFERROR(XLOOKUP(D13, Var!$P:$P, Var!$Q:$Q), ""))} -> Feature Priority 1 | L13: Medium | M13: Passed | N13: chutima.so | O13: 46204
B14: TC-R05-09 | C14: Enterprise Data Warehouse | D14: รายการ R05 - Unit Link Products [ULP] Premium Receipt VFA | E14: Functional (Happy Path) | F14: ตรวจสอบการแสดง Disclosure Type ของรายงาน R05ACC กรณี GL Code ไม่เท่ากับ 14011000 , 14012000 , 14013000, 21540005, 21540010, 21540015 , 21540006 | G14: Sheet :Reconcile Actual DATA | H14: Path วางไฟล์รายงาน R \\10.40.24.246\edw\UAT\IFRS17\Report R | I14: 1. รายงาน R05ACC : Sheet Reconcile Actual DATA - แสดง Disclosure Type สามารถ Mapping ค่ามาแสดงได้ไม่เป็นค่าว่าง | K14: {=IF(D14="", "", IFERROR(XLOOKUP(D14, Var!$P:$P, Var!$Q:$Q), ""))} -> Feature Priority 1 | L14: Medium | M14: Passed | N14: chutima.so | O14: 46204
B15: TC-R05-10 | C15: Enterprise Data Warehouse | D15: รายการ R05 - Unit Link Products [ULP] Premium Receipt VFA | E15: Functional (Happy Path) | G15: Sheet : Adjustment Posting | H15: Path วางไฟล์รายงาน R \\10.40.24.246\edw\UAT\IFRS17\Report R | I15: 1. รายงาน R06ACC : Sheet Adjustment Posting - แสดง Disclosure Type สามารถ Mapping ค่ามาแสดงได้ไม่เป็นค่าว่าง | K15: {=IF(D15="", "", IFERROR(XLOOKUP(D15, Var!$P:$P, Var!$Q:$Q), ""))} -> Feature Priority 1 | L15: Medium | M15: Passed | N15: chutima.so | O15: 46204
B16: TC-R05-11 | C16: Enterprise Data Warehouse | D16: รายการ R05 - Unit Link Products [ULP] Premium Receipt VFA | E16: Functional (Happy Path) | F16: ตรวจสอบการแสดง Plan Code ของรายงาน R05ACC กรณี GL Code ไม่เท่ากับ 14011000 , 14012000 , 14013000, 21540005, 21540010, 21540015 , 21540006 | G16: Sheet :Reconcile Actual DATA | H16: Path วางไฟล์รายงาน R \\10.40.24.246\edw\UAT\IFRS17\Report R | I16: 1. รายงาน R05ACC : Sheet Reconcile Actual DATA - แสดง Plan Code สามารถ Mapping ค่ามาแสดงได้ไม่เป็นค่าว่าง | K16: {=IF(D16="", "", IFERROR(XLOOKUP(D16, Var!$P:$P, Var!$Q:$Q), ""))} -> Feature Priority 1 | L16: Medium | M16: Passed | N16: chutima.so | O16: 46204
B17: TC-R05-12 | C17: Enterprise Data Warehouse | D17: รายการ R05 - Unit Link Products [ULP] Premium Receipt VFA | E17: Functional (Happy Path) | G17: Sheet : Adjustment Posting | H17: Path วางไฟล์รายงาน R \\10.40.24.246\edw\UAT\IFRS17\Report R | I17: 1. รายงาน R05ACC : Sheet Adjustment Posting - แสดง Plan Code สามารถ Mapping ค่ามาแสดงได้ไม่เป็นค่าว่าง | K17: {=IF(D17="", "", IFERROR(XLOOKUP(D17, Var!$P:$P, Var!$Q:$Q), ""))} -> Feature Priority 1 | L17: Medium | M17: Passed | N17: chutima.so | O17: 46204
B18: TC-R05-13 | C18: Enterprise Data Warehouse | D18: รายการ R05 - Unit Link Products [ULP] Premium Receipt VFA | E18: Functional (Happy Path) | F18: ตรวจสอบการ Summary Adj.Posting ของรายงาน R05ACC - 79120001 : Suspense - Premiums VFA | G18: Sheet :Reconcile Actual DATA | H18: Path วางไฟล์รายงาน R \\10.40.24.246\edw\UAT\IFRS17\Report R | I18: 1. รายงาน R05ACC : Sheet Adjustment Posting - Summary Adj.Posting ให้รวม Adj.Posting ของ GL ที่ไม่มี Disclosure Type (เช่น 14011000 , 14012000 , 14013000, 21540005, 21540010, 21540015 , 21540006 ) เข้าไปด้วย | K18: {=IF(D18="", "", IFERROR(XLOOKUP(D18, Var!$P:$P, Var!$Q:$Q), ""))} -> Feature Priority 1 | L18: Medium | M18: Passed | N18: chutima.so | O18: 46204
B19: รายงาน R05 (ฝ่ายคณิตศาสตร์)
B20: TC-R05-14 | C20: Enterprise Data Warehouse | D20: รายการ R05 - Unit Link Products [ULP] Premium Receipt VFA | E20: Functional (Happy Path) | F20: ตรวจสอบรายงาน R05 : ตัด GL Code หมวด 4 ที่เป็น Event code ML-0009, ML-0010 และ GL 14011000 ออก EventCode ML-0009 - 14011000 : เบี้ยประกันชีวิตค้างรับ - 40511100 : เบี้ยประกันชีวิต - ปีแรก (Premium Charge) - 40511200 : เบี้ยประกันชีวิต - ปีต่อไป (Premium Charge) - 40511500 : เบี้ยส่วนนำไปลงทุนของผู้เอาประกัน EventCode ML-0010 - 14011000 : เบี้ยประกันชีวิตค้างรับ - 40511100 : เบี้ยประกันชีวิต - ปีแรก (Premium Charge) - 40511200 : เบี้ยประกันชีวิต - ปีต่อไป (Premium Charge) - 40511500 : เบี้ยส่วนนำไปลงทุนของผู้เอาประกัน - 40512100 : เบี้ยประกันอุบัติเหตุ - ปีแรก (Phase 2) (รายการนี้ยังไม่มีใน UL) - 40512200 : เบี้ยประกันอุบัติเหตุ - ปีต่อไป (Phase 2) (รายการนี้ยังไม่มีใน UL) - 40513100 : เบี้ยประกันสุขภาพ - ปีแรก (Phase 2) (รายการนี้ยังไม่มีใน UL) - 40513200 : เบี้ยประกันสุขภาพ - ปีต่อไป (Phase 2) (รายการนี้ยังไม่มีใน UL) | H20: Path วางไฟล์รายงาน R \\10.40.24.246\edw\UAT\IFRS17\Report R | I20: 1. รายงาน R05 : ไม่แสดงข้อมูลกรมธรรม์ตัด GL Code หมวด 4 ที่เป็น Event code ML-0009, ML-0010 และ GL 14011000 EventCode ML-0009 - 14011000 : เบี้ยประกันชีวิตค้างรับ - 40511100 : เบี้ยประกันชีวิต - ปีแรก (Premium Charge) - 40511200 : เบี้ยประกันชีวิต - ปีต่อไป (Premium Charge) - 40511500 : เบี้ยส่วนนำไปลงทุนของผู้เอาประกัน EventCode ML-0010 - 14011000 : เบี้ยประกันชีวิตค้างรับ - 40511100 : เบี้ยประกันชีวิต - ปีแรก (Premium Charge) - 40511200 : เบี้ยประกันชีวิต - ปีต่อไป (Premium Charge) - 40511500 : เบี้ยส่วนนำไปลงทุนของผู้เอาประกัน - 40512100 : เบี้ยประกันอุบัติเหตุ - ปีแรก (Phase 2) (รายการนี้ยังไม่มีใน UL) - 40512200 : เบี้ยประกันอุบัติเหตุ - ปีต่อไป (Phase 2) (รายการนี้ยังไม่มีใน UL) - 40513100 : เบี้ยประกันสุขภาพ - ปีแรก (Phase 2) (รายการนี้ยังไม่มีใน UL) - 40513200 : เบี้ยประกันสุขภาพ - ปีต่อไป (Phase 2) (รายการนี้ยังไม่มีใน UL) | J20: Ref : EJ202508310001 | K20: {=IF(D20="", "", IFERROR(XLOOKUP(D20, Var!$P:$P, Var!$Q:$Q), ""))} -> Feature Priority 1 | L20: Medium | M20: Passed | N20: chutima.so | O20: 46204
B21: TC-R05-15 | C21: Enterprise Data Warehouse | D21: รายการ R05 - Unit Link Products [ULP] Premium Receipt VFA | E21: Functional (Happy Path) | F21: ตรวจสอบ GL Code ของรายงาน R05 - 14011000 : เบี้ยประกันชีวิตค้างรับ - 14012000 : เบี้ยประกันอุบัติเหตุค้างรับ - 14013000 : เบี้ยประกันสุขภาพค้างรับ - 21540005 : เบี้ยประกันชีวิตรับล่วงหน้า - 21540010 : เบี้ยประกันอุบัติเหตุรับล่วงหน้า - 21540015 : เบี้ยประกันสุขภาพรับล่วงหน้า - 21540006 : ส่วนลดเบี้ยประกันชีวิตล่วงหน้า | I21: 1. รายงาน R05 : ไม่แสดงข้อมูลกรมธรรม์ของ GL 14011000 , 14012000 , 14013000, 21540005, 21540010, 21540015 , 21540006 | K21: {=IF(D21="", "", IFERROR(XLOOKUP(D21, Var!$P:$P, Var!$Q:$Q), ""))} -> Feature Priority 1 | L21: Medium | M21: Passed | N21: chutima.so | O21: 46204 | Q21: Cancel Case เนื่องจากมีการตัด GL Code 14011000 ออกวันที่ 2026-06-29
B22: TC-R05-16 | C22: Enterprise Data Warehouse | D22: รายการ R05 - Unit Link Products [ULP] Premium Receipt VFA | E22: Functional (Happy Path) | F22: ตรวจสอบรายงาน R05 : ปรับ config cf_r05_gl_mapping - Column : TotalPremiumAmount | I22: 1. รายงาน R05 : Column TotalPremiumAmount แสดงข้อมูลถูกต้อง | K22: {=IF(D22="", "", IFERROR(XLOOKUP(D22, Var!$P:$P, Var!$Q:$Q), ""))} -> Feature Priority 1 | L22: Medium | M22: Passed | N22: chutima.so | O22: 46203
B23: TC-R05-17 | C23: Enterprise Data Warehouse | D23: รายการ R05 - Unit Link Products [ULP] Premium Receipt VFA | E23: Functional (Happy Path) | F23: ตรวจสอบรายงาน R05 : ปรับ config cf_r05_gl_mapping - Column : UnallocatedPremium | I23: 1. รายงาน R05 : Column UnallocatedPremium แสดงข้อมูลถูกต้อง | K23: {=IF(D23="", "", IFERROR(XLOOKUP(D23, Var!$P:$P, Var!$Q:$Q), ""))} -> Feature Priority 1 | L23: Medium | M23: Passed | N23: chutima.so | O23: 46203
B24: TC-R05-18 | C24: Enterprise Data Warehouse | D24: รายการ R05 - Unit Link Products [ULP] Premium Receipt VFA | E24: Functional (Happy Path) | F24: ตรวจสอบ Reconcile รายงาน OnePageSummary R05ACC (ฝ่ายบัญชี) กับ รายงาน OnePageSummary R05 (ฝ่ายคณิตศาสตร์) | I24: 1. สามารถ Reconcile รายงาน OnePageSummary R05ACC (ฝ่ายบัญชี) กับ OnePageSummary R05 (ฝ่ายคณิตศาสตร์) และ Free Template ได้จำนวนเงินเท่ากัน | K24: {=IF(D24="", "", IFERROR(XLOOKUP(D24, Var!$P:$P, Var!$Q:$Q), ""))} -> Feature Priority 1 | L24: Medium | M24: Passed | N24: chutima.so | O24: 46205
B25: รายการ R06 - Unit Link Products [ULP] Commission override VFA | F25: Process การประมวลผลข้อมูลออกรายงาน R06
B26: รายงาน R06ACC (ฝ่ายบัญชี)
B27: TC-R06-01 | C27: Enterprise Data Warehouse | D27: รายการ R06 - Unit Link Products [ULP] Commission override VFA | E27: Functional (Happy Path) | F27: ตรวจสอบ เพิ่มการดึงข้อมูล GL Code ของรายงาน R06ACC - 23521000 : ค่าจ้างค่าบำเหน็จค้างจ่าย - 15531015 : ค่าจ้างและค่าบำเหน็จจ่ายล่วงหน้า | G27: Sheet :Reconcile Actual DATA | H27: 1. Log in เข้าระบบ NBS : acc1 2. เลือกเมนู : ระบบงาน Back Office > ระบบ Enterprise Data Warehouse > ระบบ Enterprise Data Warehouse 3. เลือกเมนู : Reconcile Data > ปรับปรุงรายการทางบัญชี -> ระบุเงื่อนไขการประมวลผล -> กดปุ่ม ประมวลผล | I27: 1. รายงาน R06ACC : Sheet Reconcile Actual DATA แสดงข้อมูล บัญชี และดึงข้อมูล GL Code มาแสดงครบถ้วนถูกต้อง - 23521000 : ค่าจ้างค่าบำเหน็จค้างจ่าย - 15531015 : ค่าจ้างและค่าบำเหน็จจ่ายล่วงหน้า | K27: {=IF(D27="", "", IFERROR(XLOOKUP(D27, Var!$P:$P, Var!$Q:$Q), ""))} -> Feature Priority 1 | L27: Medium | M27: Passed | N27: chutima.so | O27: 46205
B28: TC-R06-02 | C28: Enterprise Data Warehouse | D28: รายการ R06 - Unit Link Products [ULP] Commission override VFA | E28: Functional (Happy Path) | G28: Sheet : Adjustment Posting | H28: 1. Log in เข้าระบบ NBS : acc1 2. เลือกเมนู : ระบบงาน Back Office > ระบบ Enterprise Data Warehouse > ระบบ Enterprise Data Warehouse 3. เลือกเมนู : Reconcile Data > ปรับปรุงรายการทางบัญชี -> ระบุเงื่อนไขการประมวลผล -> กดปุ่ม ประมวลผล | I28: 1. รายงาน R06ACC : Sheet Adjustment Posting แสดงข้อมูล บัญชี และดึงข้อมูล GL Code มาแสดงครบถ้วนถูกต้อง - 23521000 : ค่าจ้างค่าบำเหน็จค้างจ่าย - 15531015 : ค่าจ้างและค่าบำเหน็จจ่ายล่วงหน้า | K28: {=IF(D28="", "", IFERROR(XLOOKUP(D28, Var!$P:$P, Var!$Q:$Q), ""))} -> Feature Priority 1 | L28: Medium | M28: Passed | N28: chutima.so | O28: 46205
B29: TC-R06-03 | C29: Enterprise Data Warehouse | D29: รายการ R06 - Unit Link Products [ULP] Commission override VFA | E29: Functional (Happy Path) | F29: ตรวจสอบ การดึงข้อมูล GL Code ที่มี Collection Type : ACCRUAL ของรายงาน R06ACC | G29: Sheet :Reconcile Actual DATA | H29: 1. Log in เข้าระบบ NBS : acc1 2. เลือกเมนู : ระบบงาน Back Office > ระบบ Enterprise Data Warehouse > ระบบ Enterprise Data Warehouse 3. เลือกเมนู : Reconcile Data > ปรับปรุงรายการทางบัญชี -> ระบุเงื่อนไขการประมวลผล -> กดปุ่ม ประมวลผล | I29: 1. รายงาน R06ACC : Sheet Reconcile Actual DATA แสดงข้อมูล บัญชี ที่มี Collection Type : ACCRUAL มาแสดงครบถ้วนถูกต้อง | K29: {=IF(D29="", "", IFERROR(XLOOKUP(D29, Var!$P:$P, Var!$Q:$Q), ""))} -> Feature Priority 1 | L29: Medium | M29: Passed | N29: chutima.so | O29: 46205
B30: TC-R06-04 | C30: Enterprise Data Warehouse | D30: รายการ R06 - Unit Link Products [ULP] Commission override VFA | E30: Functional (Happy Path) | G30: Sheet : Adjustment Posting | H30: 1. Log in เข้าระบบ NBS : acc1 2. เลือกเมนู : ระบบงาน Back Office > ระบบ Enterprise Data Warehouse > ระบบ Enterprise Data Warehouse 3. เลือกเมนู : Reconcile Data > ปรับปรุงรายการทางบัญชี -> ระบุเงื่อนไขการประมวลผล -> กดปุ่ม ประมวลผล | I30: 1. รายงาน R06ACC : Sheet Adjustment Posting แสดงข้อมูล บัญชี และดึงข้อมูล GL Code มาแสดงครบถ้วนถูกต้อง - 23521000 : ค่าจ้างค่าบำเหน็จค้างจ่าย - 15531015 : ค่าจ้างและค่าบำเหน็จจ่ายล่วงหน้า | K30: {=IF(D30="", "", IFERROR(XLOOKUP(D30, Var!$P:$P, Var!$Q:$Q), ""))} -> Feature Priority 1 | L30: Medium | M30: Passed | N30: chutima.so | O30: 46205
B31: TC-R06-05 | C31: Enterprise Data Warehouse | D31: รายการ R06 - Unit Link Products [ULP] Commission override VFA | E31: Functional (Happy Path) | F31: ตรวจสอบการแสดง Receive Payment Type ของรายงาน R06ACC | G31: Sheet :Reconcile Actual DATA | H31: Path วางไฟล์รายงาน R \\10.40.24.246\edw\UAT\IFRS17\Report R | I31: 1. รายงาน R06ACC : Sheet Reconcile Actual DATA - แสดง Column Receive Payment Type - มีการ Grouping Column เพิ่ม field Receive Payment Type | K31: {=IF(D31="", "", IFERROR(XLOOKUP(D31, Var!$P:$P, Var!$Q:$Q), ""))} -> Feature Priority 1 | L31: Medium | M31: Passed | N31: chutima.so | O31: 46205
B32: TC-R06-06 | C32: Enterprise Data Warehouse | D32: รายการ R06 - Unit Link Products [ULP] Commission override VFA | E32: Functional (Happy Path) | G32: Sheet : Adjustment Posting | H32: Path วางไฟล์รายงาน R \\10.40.24.246\edw\UAT\IFRS17\Report R | I32: 1. รายงาน R06ACC : Sheet Adjustment Posting - แสดง Column Receive Payment Type - มีการ Grouping Column เพิ่ม field Receive Payment Type | K32: {=IF(D32="", "", IFERROR(XLOOKUP(D32, Var!$P:$P, Var!$Q:$Q), ""))} -> Feature Priority 1 | L32: Medium | M32: Passed | N32: chutima.so | O32: 46205
B33: TC-R06-07 | C33: Enterprise Data Warehouse | D33: รายการ R06 - Unit Link Products [ULP] Commission override VFA | E33: Functional (Happy Path) | F33: ตรวจสอบการแสดง Disclosure Type ของรายงาน R06ACC กรณี GL Code เท่ากับ 23521000 และ 15531015 | G33: Sheet :Reconcile Actual DATA | H33: Path วางไฟล์รายงาน R \\10.40.24.246\edw\UAT\IFRS17\Report R | I33: 1. รายงาน R06ACC : Sheet Reconcile Actual DATA - แสดง Disclosure Type แสดงเป็นค่าว่าง | K33: {=IF(D33="", "", IFERROR(XLOOKUP(D33, Var!$P:$P, Var!$Q:$Q), ""))} -> Feature Priority 1 | L33: Medium | M33: Passed | N33: chutima.so | O33: 46205
B34: TC-R06-08 | C34: Enterprise Data Warehouse | D34: รายการ R06 - Unit Link Products [ULP] Commission override VFA | E34: Functional (Happy Path) | G34: Sheet : Adjustment Posting | H34: Path วางไฟล์รายงาน R \\10.40.24.246\edw\UAT\IFRS17\Report R | I34: 1. รายงาน R06ACC : Sheet Adjustment Posting - แสดง Disclosure Type แสดงเป็นค่าว่าง | K34: {=IF(D34="", "", IFERROR(XLOOKUP(D34, Var!$P:$P, Var!$Q:$Q), ""))} -> Feature Priority 1 | L34: Medium | M34: Passed | N34: chutima.so | O34: 46205
B35: TC-R06-09 | C35: Enterprise Data Warehouse | D35: รายการ R06 - Unit Link Products [ULP] Commission override VFA | E35: Functional (Happy Path) | F35: ตรวจสอบการแสดง Plan Code ของรายงาน R06ACC กรณี GL Code เท่ากับ 23521000 และ 15531015 | G35: Sheet :Reconcile Actual DATA | H35: Path วางไฟล์รายงาน R \\10.40.24.246\edw\UAT\IFRS17\Report R | I35: 1. รายงาน R06ACC : Sheet Reconcile Actual DATA - แสดง Plan Code แสดงเป็นค่าว่าง | K35: {=IF(D35="", "", IFERROR(XLOOKUP(D35, Var!$P:$P, Var!$Q:$Q), ""))} -> Feature Priority 1 | L35: Medium | M35: Passed | N35: chutima.so | O35: 46205
B36: TC-R06-10 | C36: Enterprise Data Warehouse | D36: รายการ R06 - Unit Link Products [ULP] Commission override VFA | E36: Functional (Happy Path) | G36: Sheet : Adjustment Posting | H36: Path วางไฟล์รายงาน R \\10.40.24.246\edw\UAT\IFRS17\Report R | I36: 1. รายงาน R06ACC : Sheet Adjustment Posting - แสดง Plan Code แสดงเป็นค่าว่าง | K36: {=IF(D36="", "", IFERROR(XLOOKUP(D36, Var!$P:$P, Var!$Q:$Q), ""))} -> Feature Priority 1 | L36: Medium | M36: Passed | N36: chutima.so | O36: 46205
B37: TC-R06-11 | C37: Enterprise Data Warehouse | D37: รายการ R06 - Unit Link Products [ULP] Commission override VFA | E37: Functional (Happy Path) | F37: ตรวจสอบการแสดง Disclosure Type ของรายงาน R06ACC กรณี GL Code ไม่เท่ากับ 23521000 และ 15531015 | G37: Sheet :Reconcile Actual DATA | H37: Path วางไฟล์รายงาน R \\10.40.24.246\edw\UAT\IFRS17\Report R | I37: 1. รายงาน R06ACC : Sheet Reconcile Actual DATA - แสดง Disclosure Type สามารถ Mapping ค่ามาแสดงได้ไม่เป็นค่าว่าง | K37: {=IF(D37="", "", IFERROR(XLOOKUP(D37, Var!$P:$P, Var!$Q:$Q), ""))} -> Feature Priority 1 | L37: Medium | M37: Passed | N37: chutima.so | O37: 46205
B38: TC-R06-12 | C38: Enterprise Data Warehouse | D38: รายการ R06 - Unit Link Products [ULP] Commission override VFA | E38: Functional (Happy Path) | G38: Sheet : Adjustment Posting | H38: Path วางไฟล์รายงาน R \\10.40.24.246\edw\UAT\IFRS17\Report R | I38: 1. รายงาน R06ACC : Sheet Adjustment Posting - แสดง Disclosure Type สามารถ Mapping ค่ามาแสดงได้ไม่เป็นค่าว่าง | K38: {=IF(D38="", "", IFERROR(XLOOKUP(D38, Var!$P:$P, Var!$Q:$Q), ""))} -> Feature Priority 1 | L38: Medium | M38: Passed | N38: chutima.so | O38: 46205
B39: TC-R06-13 | C39: Enterprise Data Warehouse | D39: รายการ R06 - Unit Link Products [ULP] Commission override VFA | E39: Functional (Happy Path) | F39: ตรวจสอบการแสดง Plan Code ของรายงาน R06ACC กรณี GL Code ไม่เท่ากับ 23521000 และ 15531015 | G39: Sheet :Reconcile Actual DATA | H39: Path วางไฟล์รายงาน R \\10.40.24.246\edw\UAT\IFRS17\Report R | I39: 1. รายงาน R06ACC : Sheet Reconcile Actual DATA - แสดง Plan Code สามารถ Mapping ค่ามาแสดงได้ไม่เป็นค่าว่าง | K39: {=IF(D39="", "", IFERROR(XLOOKUP(D39, Var!$P:$P, Var!$Q:$Q), ""))} -> Feature Priority 1 | L39: Medium | M39: Passed | N39: chutima.so | O39: 46205
B40: TC-R06-14 | C40: Enterprise Data Warehouse | D40: รายการ R06 - Unit Link Products [ULP] Commission override VFA | E40: Functional (Happy Path) | G40: Sheet : Adjustment Posting | H40: Path วางไฟล์รายงาน R \\10.40.24.246\edw\UAT\IFRS17\Report R | I40: 1. รายงาน R06ACC : Sheet Adjustment Posting - แสดง Plan Code สามารถ Mapping ค่ามาแสดงได้ไม่เป็นค่าว่าง | K40: {=IF(D40="", "", IFERROR(XLOOKUP(D40, Var!$P:$P, Var!$Q:$Q), ""))} -> Feature Priority 1 | L40: Medium | M40: Passed | N40: chutima.so | O40: 46205
B41: TC-R06-15 | C41: Enterprise Data Warehouse | D41: รายการ R05 - Unit Link Products [ULP] Premium Receipt VFA | E41: Functional (Happy Path) | F41: ตรวจสอบการ Summary Adj.Posting ของรายงาน R06ACC - 79120002 : Suspense - Commission_VFA | G41: Sheet :Reconcile Actual DATA | H41: Path วางไฟล์รายงาน R \\10.40.24.246\edw\UAT\IFRS17\Report R | I41: 1. รายงาน R06ACC : Sheet Adjustment Posting - Summary Adj.Posting ให้รวม Adj.Posting ของ GL ที่ไม่มี Disclosure Type (เช่น 15531015, 23521000) เข้าไปด้วย | K41: {=IF(D41="", "", IFERROR(XLOOKUP(D41, Var!$P:$P, Var!$Q:$Q), ""))} -> Feature Priority 1 | L41: Medium | M41: Passed | N41: chutima.so | O41: 46205
...

Sheet Redmine
A1: Redmine: Tracker "Defect" | C1: ตัวอย่างการระบุเงื่อนไข Where ใน Column C2 - กรณีต้องการหลายค่า ให้ใช้คำสั่ง matches เช่น tracker matches 'Defect|Task' - กรณีต้องการหลาย UR หรือ หลายโครงการ ใช้คำสั่ง เช่น ตัวอย่างทำ 4 UR พร้อมๆกัน project matches '.*UR 20250098.*|.*UR 20250127.*|.*UR 20250137.*|.*UR 20250096.*'
A2: เงื่อนไขการดึงข้อมูล Redmine | C2: where tracker = 'Defect' and phase='SIT' and project ='UR 20260041 - R13 Expense allocation Improvement'
A3: id | B3: project | C3: tracker | D3: status | E3: priority | F3: author | G3: assigned_to | H3: parent | I3: subject | J3: description | K3: start_date | L3: due_date | M3: done_ratio | N3: is_private | O3: estimated_hours | P3: total_estimated_hours | Q3: spent_hours | R3: total_spent_hours | S3: created_on | T3: updated_on | U3: closed_on | V3: root_cause | W3: application | X3: screen | Y3: phase
A4: =IFERROR(__xludf.DUMMYFUNCTION("LET( url, ""https://docs.google.com/spreadsheets/d/1aQvBSBqzTssy3xc8GrcZkgkGHZrsM_cM_Jx0QN_s8Og"", headRange, ""All_Redmine!A1:Y1"", dataRange, ""All_Redmine!A3:Y"", headers, INDEX(IMPORTRANGE(url, headRange), 1, ), data, IMPORTRANGE(url, da"&"taRange), tokens, {""id"",""project"",""tracker"",""status"",""priority"",""author"",""assigned_to"",""parent"",""subject"",""description"",""start_date"",""due_date"",""done_ratio"",""is_private"",""estimated_hours"",""total_estimated_hours"",""spent_"&"hours"",""total_spent_hours"",""created_on"",""updated_on"",""closed_on"",""root_cause"",""screen"",""phase""}, q_raw, IF(LEN(C2), "" ""&C2, """"), q_map, REDUCE( q_raw, tokens, LAMBDA(acc, t, LET( idx, IFERRO"&"R(MATCH(t, headers, 0), 0), IF(idx, SUBSTITUTE(acc, t, ""Col""&idx), acc) ) ) ), QUERY(data, ""select *""&q_map, 0) ) "),"#REF!") -> #REF!

Sheet Test Data
A1: Test Data

Sheet Var
A1: SIT | B1: Test Status | C1: Test Status Description | D1: Issue Status | E1: Yes/No | F1: Root Cause | G1: Root Cause Issue Type | H1: Root Cause Category | I1: Holiday | J1: Holiday Description | K1: Test Execution Order | L1: Objective | M1: Feature Priority | N1: Test Cases Priority | O1: Application | P1: Feature | Q1: Feature Priority | R1: Test Case Type | S1: Test Case Type Definition | T1: Test Cases Priority
A2: Development | B2: Not Ready for Test | C2: Not Ready for Test = ส่วนที่ไม่พร้อมทดสอบ | D2: Not Start | E2: Yes | F2: Under Investigated | G2: Under Investigated | H2: Under Investigated | I2: 45292 | J2: วันขึ้ึ้นปีใหม่ | K2: 1 | L2: "หัวใจของระบบต้องรอด": ยืนยันว่าฟังก์ชันหลัก (Happy Path), ความปลอดภัย (Security), การเชื่อมต่อ (Integration) และสูตรคำนวณทางธุรกิจ (Business Logic) ของฟีเจอร์สำคัญที่สุดทำงานถูกต้อง 100% | M2: Feature Priority 1 | N2: High | O2: Enterprise Data Warehouse | P2: รายการ R05 - Unit Link Products [ULP] Premium Receipt VFA | Q2: Feature Priority 1 | R2: Functional (Happy Path) | S2: การทำงานหลักตามขั้นตอนปกติที่ผู้ใช้ต้องทำให้สำเร็จ | T2: High
A3: SIT | B3: Not Start | C3: Not Start = ยังไม่เริ่มทดสอบ | D3: In Progress | E3: No | F3: Requirement Change | G3: Change Request | H3: Requirement | I3: 45293 | J3: ชดเชยวันสิ้นปี (วันอาทิตย์ที่ 31 ธันวาคม 2566) | K3: 2 | L3: "ฟีเจอร์หลักต้องแม่นยำและเสถียร": ตรวจสอบการจัดการเมื่อเกิดข้อผิดพลาด (Negative Test), รูปแบบข้อมูล (Input Validation), ความเร็ว (Performance) และการรองรับผู้ใช้ (Load) ของฟีเจอร์หลัก | M3: Feature Priority 1 | N3: Medium | P3: รายการ R06 - Unit Link Products [ULP] Commission override VFA | Q3: Feature Priority 1 | R3: Security | S3: การตรวจสอบสิทธิ์เข้าใช้งานและความปลอดภัยของข้อมูล | T3: High
A4: UAT | B4: In Progress | C4: In Progress = อยู่ระหว่างการทดสอบ | D4: Pending | F4: Missing Requirement | G4: Change Request | H4: Requirement | I4: 45348 | J4: ชดเชยวันมาฆบูชา (วันเสาร์ที่ 24 กุมภาพันธ์ 2567) | K4: 3 | L4: "ระบบเสริมพื้นฐานต้องผ่าน": ตรวจสอบการทำงานหลักตามขั้นตอนปกติ (Happy Path) และความปลอดภัยของฟีเจอร์สนับสนุนที่สำคัญ เพื่อให้มั่นใจว่าทำงานร่วมกับระบบหลักได้ | M4: Feature Priority 2 | N4: High | P4: รายการ R02 - Ordinary Products [OP] Commission override GMM | Q4: Feature Priority 1 | R4: Integration | S4: การเชื่อมต่อรับส่งข้อมูลระหว่างระบบหรือ API | T4: High
A5: Go-live | B5: Pending | C5: Pending = ไม่สามารถทดสอบต่อได้ | D5: Completed | F5: Incorrect Specification | G5: Bug | H5: Design | I5: 45390 | J5: ชดเชยวันพระบาทสมเด็จพระพุทธยอดฟ้าจุฬาโลกมหาราช และวันที่ระลึกมหาจักรีบรมราชวงศ์ (วันเสาร์ที่ 6 เมษายน 2567) | K5: 4 | L5: "ระบบเสริมต้องเสถียร": ทดสอบการดักจับข้อผิดพลาด (Negative) และความถูกต้องของข้อมูล (Input Validation) ในฟีเจอร์สนับสนุน เพื่อลดความเสี่ยงของข้อมูลผิดเพี้ยน | M5: Feature Priority 2 | N5: Medium | P5: รายการ R14 - Ordinary Products [OP] APL and PL GMM | Q5: Feature Priority 1 | R5: Business Logic | S5: การคำนวณและเงื่อนไขตามกฎธุรกิจ (เช่น สูตรภาษี, ส่วนลด) | T5: High
B6: Failed | C6: Failed = ผลการทดสอบไม่ผ่าน | D6: Deferred | F6: Application Defect | G6: Bug | H6: Development | I6: 45397 | J6: วันสงกรานต์ | K6: 5 | L6: "ความสวยงามของระบบหลัก": ตรวจสอบ UI/UX และการแสดงผลตามอุปกรณ์ (Compatibility) ของฟีเจอร์ที่คนใช้งานบ่อย เพื่อสร้างประสบการณ์ที่ดีแก่ผู้ใช้ | M6: Feature Priority 1 | N6: Low | Q6: Feature Priority 2 | R6: Negative Test | S6: การจัดการของระบบเมื่อเกิดข้อผิดพลาด (เช่น ใส่ข้อมูลผิดแล้วระบบต้องไม่ค้าง) | T6: Medium
B7: Passed with Condition | C7: Passed with Condition = ผลการทดสอบผ่านแบบมีเงื่อนไข | F7: Configuration Defect | G7: Bug | H7: Development | I7: 45398 | J7: ชดเชยวันสงกรานต์ (วันเสาร์ที่ 13 เมษายน 2567 และ วันอาทิตย์ที่ 14 เมษายน 2567) | K7: 6 | L7: "ความสมบูรณ์ของระบบเสริม": ตรวจสอบความถูกต้องของการจัดวางหน้าจอและภาษา (Localization) ของฟีเจอร์สนับสนุน | M7: Feature Priority 2 | N7: Low | R7: Input Validation | S7: การตรวจสอบรูปแบบข้อมูลพื้นฐาน (เช่น รูปแบบ Email, เบอร์โทร) | T7: Medium
B8: Passed | C8: Passed = ผลการทดสอบผ่าน | F8: Missing Standard Practices | G8: Bug | H8: Development | I8: 45413 | J8: วันแรงงานแห่งชาติ | K8: 7 | L8: "ฟังก์ชันเสริมทำงานถูกต้อง": ตรวจสอบการทำงานเบื้องต้นของฟีเจอร์ส่วนเสริมที่มีคนใช้งานน้อย | M8: Feature Priority 3 | N8: High | R8: Performance | S8: ความเร็วในการโหลดหน้าจอทั่วไป (Response Time) ต้องไม่ช้าเกินไปจนผู้ใช้เลิกใช้ | T8: Medium
B9: Cancelled | C9: Cancelled = ยกเลิกการทดสอบ | F9: Performance Issue | G9: Bug | H9: Development | I9: 45418 | J9: ชดเชยวันฉัตรมงคล (วันเสาร์ที่ 4 พฤษภาคม 2567) | K9: 8 | L9: "ความเสถียรของฟังก์ชันเสริม": เก็บเคส Negative และ Validation ของฟีเจอร์ส่วนเสริมตามเวลาที่เหลือ | M9: Feature Priority 3 | N9: Medium | R9: Load | S9: ระบบรองรับคนจำนวนมากเข้าใช้งานพร้อมกัน | T9: Medium
F10: UI/UX | G10: Bug | H10: Development | I10: 45434 | J10: วันวิสาขบูชา | K10: 9 | L10: "เก็บรายละเอียดส่วนสุดท้าย": ตรวจสอบ UI/UX ของฟีเจอร์ส่วนเสริมเพื่อความเป๊ะของระบบในภาพรวม | M10: Feature Priority 3 | N10: Low | R10: UI/UX | S10: ความถูกต้องของการจัดวางหน้าจอ สี ฟอนต์ และความง่ายในการใช้งาน | T10: Low
F11: Question/Misunderstanding | G11: Question | H11: Testing | I11: 45446 | J11: วันเฉลิมพระชนมพรรษา สมเด็จพระนางเจ้าสุทิดา พัชรสุธาพิมลลักษณ พระบรมราชินี | R11: Compatibility | S11: Compatibility: การแสดงผลตามอุปกรณ์ | T11: Low
F12: Incorrect Test Data | G12: Question | H12: Testing | I12: 45495 | J12: ชดเชยวันอาสาฬหบูชา (วันเสาร์ที่ 20 กรกฎาคม 2567)
F13: Environment Issue | G13: Question | H13: Testing | I13: 45502 | J13: ชดเชยวันเฉลิมพระชนมพรรษา พระบาทสมเด็จพระเจ้าอยู่หัว (วันอาทิตย์ที่ 28 กรกฎาคม 2567)
F14: Production Issue | G14: Production Issue | H14: Production Issue | I14: 45516 | J14: วันเฉลิมพระชนมพรรษา สมเด็จพระนางเจ้าสิริกิติ์ พระบรมราชินีนาถ พระบรมราชชนนีพันปีหลวง และวันแม่แห่งชาติ
F15: Production Data | G15: Production Issue | H15: Production Issue | I15: 45579 | J15: ชดเชยวันคล้ายวันสวรรคต พระบาทสมเด็จพระบรมชนกาธิเบศร มหาภูมิพลอดุลยเดชมหาราช บรมนาถบพิตร (วันอาทิตย์ที่ 13 ตุลาคม 2567)
I16: 45649 | J16: วันปิยมหาราช
I17: 45631 | J17: วันคล้ายวันพระบรมราชสมภพ พระบาทสมเด็จพระบรมชนกาธิเบศร มหาภูมิพลอดุลยเดชมหาราช บรมนาถบพิตร วันชาติ และวันพ่อแห่งชาติ
I18: 45636 | J18: วันรัฐธรรมนูญ
I19: 45657 | J19: วันสิ้นปี
I20: 45658 | J20: วันขึ้นปีใหม่
I21: 45700 | J21: วันมาฆบูชา
I22: 45754 | J22: วันพระบาทสมเด็จพระพุทธยอดฟ้าจุฬาโลกมหาราช และ วันที่ระลึกมหาจักรีบรมราชวงศ์
I23: 45761 | J23: วันสงกรานต์
I24: 45762 | J24: วันสงกรานต์
I25: 45778 | J25: วันแรงงานแห่งชาติ
I26: 45782 | J26: วันฉัตรมงคล
I27: 45789 | J27: วันวิสาขบูชา
... I56: 46387 | J56: วันสิ้นปี
